Workbook

Sheet Geral
F3: Controle de Equipamentos Offshore | Q3: Equipe a bordo
F5: Sonda: | G5: SS-73 | L5: Poço: | M5: 7-BAZ-3-ESS | Q5: Supervisor | S5: JACKSON FERREIRA | U5: Supervisor | W5: RAFAEL DAMÁSIO
Q6: Técnico | S6: YASMIN FERREIRA | U6: Técnico | W6: RAFAEL BELO
F7: Data: | G7: 46206 | L7: Campo: | M7: BALEIA AZUL | Q7: Técnico | S7: GENIS DA HORA | U7: Técnico | W7: WAGNER SMITH
B9: EQUIPAMENTOS
B11: Item | C11: Equip. | D11: Qtd | E11: NP | F11: NS | G11: Descrição do item | K11: Localização | L11: Dimensões em metros (C x L x A) | M11: Peso (Kg) | N11: Eslinga | O11: Solic. Material | Q11: RT de Embarque | R11: Data de Embarque | S11: RT de Desembarque | T11: Data de Desembarque | U11: Origem | V11: Destino | W11: Observação
B12: =IF(G12="","",1) -> 1 | C12: JUNTAS | D12: 0 | E12: 495094 | F12: N/A | G12: STRESS JOINT 43FT | L12: ok | N12: N/A
B13: =IF(G13="","",1+B12) -> 2 | D13: 0 | E13: 495095 | F13: N/A | G13: STRESS JOINT TRANSPORT SKID | N13: ='Controle de Eslingas'!#REF! -> #REF!
B14: =IF(G14="","",1+B13) -> 3 | D14: 0 | E14: 495096 | F14: N/A | G14: MECHANICAL RAPID CONNECTOR | N14: N/A
B15: =IF(G15="","",1+B14) -> 4 | D15: 113 | E15: 495075 | F15: N/A | G15: PIPE DRILL 6.5/8" - XT-MF 69 | K15: Em operação | L15: ok | N15: N/A
B16: =IF(G16="","",1+B15) -> 5 | D16: 1 | E16: 495078 | F16: NPAE-00958 / PPJ-019 | G16: PUP JOINT 8' - XT-MF 69 | K16: Pipe Deck | L16: ok | N16: N/A
B17: =IF(G17="","",1+B16) -> 6 | D17: 1 | E17: 495078 | F17: NPAE-00959 / PPJ-020 | G17: PUP JOINT 8' - XT-MF 69 | K17: Pipe Deck | L17: ok | N17: N/A
B18: =IF(G18="","",1+B17) -> 7 | D18: 0 | E18: 495077 | F18: N/A | G18: PUP JOINT 10' - XT-MF 69 | N18: N/A
B19: =IF(G19="","",1+B18) -> 8 | D19: 0 | E19: 495077 | F19: N/A | G19: PUP JOINT 10' - XT-MF 69 | N19: N/A
B20: =IF(G20="","",1+B19) -> 9 | D20: 1 | E20: 495076 | F20: NPAE-00967 / PPJ-001 | G20: PUP JOINT 20' - XT-MF 69 | K20: Pipe Deck | L20: ok | N20: N/A | W20: Se encontra na JRC
B21: =IF(G21="","",1+B20) -> 10 | D21: 0 | E21: 495076 | F21: N/A | G21: PUP JOINT 20' - XT-MF 69 | N21: N/A
B22: =IF(G22="","",1+B21) -> 11 | D22: 1 | E22: 495081 | F22: SSUB-001 | G22: SAVER SUB BOX X BOX | K22: N/A | N22: N/A
B23: =IF(G23="","",1+B22) -> 12 | D23: 1 | E23: 495082 | F23: SSUB-011 | G23: SAVER SUB BOX X PIN | K23: Dpr crossover transport basket | L23: ok | N23: N/A
B24: =IF(G24="","",1+B23) -> 13 | D24: 0 | E24: 495083 | F24: N/A | G24: SAVER SUB PIN X PIN | L24: ok | N24: N/A
B25: =IF(G25="","",1+B24) -> 14 | D25: 0 | E25: 495106 | F25: N/A | G25: LUBRICATOR VALVE ASSEMBLY | N25: N/A
B26: =IF(G26="","",1+B25) -> 15 | D26: 0 | E26: 495084 | F26: N/A | G26: RISER ACCESSORIES TRANSPORT BASKET | N26: ='Controle de Eslingas'!#REF! -> #REF!
B27: =IF(G27="","",1+B26) -> 16 | C27: ADAPTADORES | D27: 0 | E27: 495097 | F27: N/A | G27: ADAPTER HUB 11” X RISER MC 12D | N27: N/A
B28: =IF(G28="","",1+B27) -> 17 | D28: 0 | E28: 495098 | F28: N/A | G28: ADAPTER HUB 11” X RISER MC 12DX | N28: N/A
B29: =IF(G29="","",1+B28) -> 18 | D29: 0 | E29: 495099 | F29: N/A | G29: ADAPTER XT-MF69 (BOX) X MC 8D (BOX) | N29: N/A
B30: =IF(G30="","",1+B29) -> 19 | D30: 0 | E30: 495100 | F30: N/A | G30: ADAPTER XT-MF69 (BOX) X MC 8DX (BOX) | N30: N/A
B31: =IF(G31="","",1+B30) -> 20 | D31: 1 | E31: 495101 | F31: ADH-012 | G31: ADAPTER HUB 11” X FLANGE 11” 5X1 | K31: Main Deck | L31: ok | N31: N/A | W31: DECK AO LADO DO CONTAINER DE OFICINA
B32: =IF(G32="","",1+B31) -> 21 | D32: 1 | E32: 495102 | F32: ADH-013 | G32: ADAPTER HUB 11” X FLANGE 11” 4X2 | K32: Main Deck | L32: ok | N32: N/A | W32: DECK AO LADO DO CONTAINER DE OFICINA
B33: =IF(G33="","",1+B32) -> 22 | D33: 0 | E33: 495103 | G33: ADAPTER HUB 11” X FLANGE 11” 10K | N33: N/A
B34: =IF(G34="","",1+B33) -> 23 | D34: 1 | E34: 495104 | F34: ADH-022 | G34: ADAPTER HUB 11” X FLANGE 13 5/8” 5X1 | K34: Main Deck | L34: ok | N34: N/A | W34: DECK AO LADO DO CONTAINER DE OFICINA
B35: =IF(G35="","",1+B34) -> 24 | D35: 0 | E35: 495105 | F35: N/A | G35: HUB ADAPTER TRANSPORT SKID | N35: ='Controle de Eslingas'!#REF! -> #REF!
B36: =IF(G36="","",1+B35) -> 25 | C36: CROSSOVER'S | D36: 1 | E36: 495085 | F36: CRO-004 | G36: CROSSOVER DPR X 4 ½” IF | K36: Drill Floor | N36: N/A
B37: =IF(G37="","",1+B36) -> 26 | D37: 1 | E37: 495086 | F37: CRO-013 | G37: CROSSOVER DPR X 6 5/8” VAM DPR SR | K37: Em operação | L37: ok | N37: N/A | W37: EM OPERACÇÃO
B38: =IF(G38="","",1+B37) -> 27 | D38: 1 | E38: 495087 | F38: CRO-015 | G38: CROSSOVER DPR X 6 5/8” VAM DPR HP | K38: DPR crossover transport basket | L38: ok | N38: N/A | W38: 100T14324
B39: =IF(G39="","",1+B38) -> 28 | D39: 0 | E39: 495088 | G39: CROSSOVER DPR X 6 5/8” FH | L39: ok | N39: N/A | W39: 100T14324
B40: =IF(G40="","",1+B39) -> 29 | D40: 1 | E40: 495089 | F40: CRO-031 | G40: CROSSOVER DPR X DP 5” NC50 | K40: Drill Floor | L40: ok | N40: N/A | W40: CONTENIER 100T14324
B41: =IF(G41="","",1+B40) -> 30 | D41: 0 | E41: 497277 | F41: N/A | G41: CROSSOVER STUB ACME PIN X XT-MF69 BOX | N41: N/A
B42: =IF(G42="","",1+B41) -> 31 | D42: 0 | E42: 497278 | F42: N/A | G42: CROSSOVER STUB ACME PIN X XT-MF69 PIN | N42: N/A
B43: =IF(G43="","",1+B42) -> 32 | D43: 1 | E43: 496064 | F43: CRO-036 | G43: CROSSOVER DPR X SWIVEL | K43: Em operação | N43: N/A | W43: Cesta de XO, CBX-224
B44: =IF(G44="","",1+B43) -> 33 | D44: 0 | E44: 495093 | G44: DPR CROSSOVER TRANSPORT BASKET | N44: ='Controle de Eslingas'!I11 -> E53212
B45: =IF(G45="","",1+B44) -> 34 | D45: 1 | E45: 495072 | F45: SFTUC-004 | G45: SFT UPPER CROSSOVER 8 ¼” STUB ACME X 8 ¼” ACME BOWEN | K45: Dpr crossover transport basket | L45: OK | N45: N/A | W45: CONTENIER 100T14324
...

Sheet Consumíveis
F3: =Geral!F3 -> Controle de Equipamentos Offshore | N3: =Geral!Q3 -> Equipe a bordo
F5: =Geral!F5 -> Sonda: | G5: =Geral!G5 -> SS-73 | J5: =Geral!L5 -> Poço: | K5: =Geral!M5 -> 7-BAZ-3-ESS | N5: =Geral!Q5 -> Supervisor | P5: =Geral!S5 -> JACKSON FERREIRA | R5: =Geral!U5 -> Supervisor | T5: =Geral!W5 -> RAFAEL DAMÁSIO
G6: Data teste de carga | N6: =Geral!Q6 -> Técnico | P6: =Geral!S6 -> YASMIN FERREIRA | R6: =Geral!U6 -> Técnico | T6: =Geral!W7 -> WAGNER SMITH
F7: =Geral!F7 -> Data: | G7: =Geral!G7 -> 46206 | J7: =Geral!L7 -> Campo: | K7: =Geral!M7 -> BALEIA AZUL | N7: =Geral!Q7 -> Técnico | P7: =Geral!S7 -> GENIS DA HORA | R7: =Geral!U7 -> Técnico | T7: =Geral!#REF! -> #REF!
B9: EQUIPAMENTOS
B11: Item | C11: QNT | D11: NP | E11: NS | G11: DESCRIÇÃO | L11: APLICAÇÃO | P11: LOCALIZAÇÃO | R11: OBSERVAÇÃO
B12: 1 | C12: 1 | D12: N/A | E12: N/A | G12: LUBRAX CALCIUM GR2 | L12: N/A | P12: Container 10DRY14436 | R12: 20 kg
B13: 2 | C13: 1 | D13: N/A | E13: N/A | G13: LUBRAX CALCIUM ECO 2 | L13: N/A | P13: Container 10DRY14436 | R13: 20 kg
B14: 3 | C14: 1 | D14: N/A | E14: N/A | G14: MOBILGEAR SHC XMP320 SINTHETIC WIND TURBINE | L14: N/A | P14: Container 10DRY14436 | R14: 10 l
B15: 4 | C15: 1 | D15: N/A | E15: N/A | G15: Óleo Hidráulico HF 101N (Enerpac) | L15: N/A | P15: Container 10DRY14436 | R15: 4 l
B16: 5 | C16: 1 | D16: N/A | E16: N/A | G16: Óleo Hidráulico HF 100N (Enerpac) | L16: N/A | P16: N/A | R16: 1 l
B17: 6 | C17: 1 | D17: N/A | E17: N/A | G17: TELLUS S2 M 46 | L17: N/A | P17: Container 10DRY14436 | R17: 20 l
B18: 7 | C18: 1 | D18: N/A | E18: N/A | G18: VG 10 | L18: LUBRIFIL | P18: Container 10DRY14436 | R18: 1 l
B19: 8 | C19: 1 | D19: N/A | E19: N/A | G19: KOPR-KOTE | L19: Rosca XTMF-69 | P19: Container 10DRY14436 | R19: 8 kg | U19: b
C20: 0 | D20: N/A | E20: N/A | G20: PETRONAS TUTELA MR-LM (D472E123) | L20: N/A | P20: N/A
C21: 2 | D21: N/A | E21: N/A | G21: TUFLUBE ALLWEATHER | L21: GRAXA PARA ENGRENAGEM | P21: Container 10DRY14436 | R21: 4 + 4 kg
C22: 1 | D22: N/A | E22: N/A | G22: MOBILGEAR 600 XP 680 | L22: N/A | P22: Container 10DRY14436 | R22: 20 l
C23: 1 | D23: N/A | E23: N/A | G23: RENOLIT FEP 2 | L23: N/A | P23: Container 10DRY14436 | R23: 18 kg
B24: =IF(G24="","",B23+1) -> 1 | C24: 1 | D24: N/A | E24: N/A | G24: TUFGEAR UNIVERSAL | L24: N/A | P24: Container 10DRY14436 | R24: 4 kg
B25: =IF(G25="","",B24+1) -> 2 | C25: 1 | D25: N/A | E25: N/A | G25: TELLUS 68 | L25: N/A | P25: Container 10DRY14436 | R25: 20 l
B26: =IF(G26="","",B25+1) -> 3 | C26: 10 | D26: N/A | E26: N/A | F26: N/A | G26: HW - 443 | L26: N/A | P26: CBAT-468 | R26: 200 L
B27: =IF(#REF!="","",B26+1) -> #REF!
B28: =IF(G28="","",B27+1)
B29: =IF(G29="","",B28+1)
B30: =IF(G30="","",B29+1)
B31: =IF(G31="","",B30+1)
B32: =IF(G32="","",B31+1)
B33: =IF(G33="","",B32+1)
B34: =IF(G34="","",B33+1)
B35: =IF(G35="","",B34+1)
B36: =IF(G36="","",B35+1)
B37: =IF(G37="","",B36+1)
B38: =IF(G38="","",B37+1)
B39: =IF(G39="","",B38+1) | D39: -
B40: =IF(G40="","",B39+1) | D40: - | E40: -
B41: =IF(G41="","",B40+1) | D41: - | E41: -
B42: =IF(G42="","",B41+1) | D42: - | E42: -
B43: =IF(G43="","",B42+1) | D43: - | E43: -
B44: =IF(G44="","",B43+1) | D44: - | E44: -
B45: =IF(G45="","",B44+1) | D45: - | E45: -
...

Sheet Controle de Eslingas
F3: =Geral!F3 -> Controle de Equipamentos Offshore | Q3: =Geral!Q3 -> Equipe a bordo
F5: =Geral!F5 -> Sonda: | G5: =Geral!G5 -> SS-73 | L5: =Geral!L5 -> Poço: | M5: =Geral!M5 -> 7-BAZ-3-ESS | Q5: Supervisor | S5: RAFAEL DAMÁSIO | U5: Supervisor | W5: RODOLFO RIBEIRO
G6: Data teste de carga | M6: Data da Inspeção | Q6: Técnico | S6: WAGNER SMITH | U6: Técnico | W6: GENIS HORA
F7: =Geral!F7 -> Data: | G7: 46079 | L7: =Geral!L7 -> Campo: | M7: =Geral!M7 -> BALEIA AZUL | Q7: Técnico | S7: LEANDRO CARVALHO | U7: Técnico | W7: YASMIN PEREIRA
B9: EQUIPAMENTOS
B10: Item | C10: NP | D10: NS | E10: Descrição do item | I10: ID Eslinga | J10: Especificação da Eslinga | K10: Validade da Eslinga | L10: Data Cert. equip. / Skid | M10: Validade teste carga equip. / skid | N10: Localização da Eslinga | R10: Solic. Material | S10: RT de Embarque | T10: Data de Embarque | U10: RT de Desembarque | V10: Data de Desembarque | W10: Observação
B11: 1 | C11: 495008 | D11: HPU-239 | E11: HPU W/ INTEGRATED OPEN SEA CONTROL PANEL | I11: E53212 | J11: N/A | K11: 46102 | L11: N/A | M11: 46102
B12: 2 | C12: 498056 | D12: WV-033 | E12: CONTROL CABIN | I12: AA9840 | J12: N/A | K12: 46102 | L12: N/A | M12: 46102
B13: 3 | C13: 495624 | D13: WC-002 | E13: WORKSHOP CONTAINER | I13: 551SM | J13: N/A | K13: 46179 | L13: 46180 | M13: N/A
B14: 31 | C14: N/A | D14: CBAD-647 | E14: Cesta da Cased wear Joint | I14: SOS05A/00052 | J14: N/A | K14: 46192 | L14: N/A | M14: 46193
B15: 5 | C15: N/A | D15: R-16-15-26198 | E15: SKID N2 | I15: 104416/0002 | J15: N/A | K15: 46296 | L15: N/A | M15: 46296
B16: 6 | C16: N/A | D16: MAC1008 | E16: ESLINGA DA UNIDADE DE INJEÇÃO MAC-1008 | I16: MAC-1008-S2 | J16: N/A | K16: 46325 | L16: N/A | M16: N/A
B17: 32 | C17: N/A | D17: CBAT 468 | E17: Cesta de HW | I17: SOS12A/0023 | J17: N/A | K17: 46420 | L17: N/A | M17: 46389
B18: 8 | C18: N/A | D18: N/A | E18: N\A | I18: N/A | J18: N/A
B19: 9 | C19: N/A | D19: N/A | E19: CARRETEL TH | I19: NA | J19: N/A | K19: 46407 | L19: N/A | M19: 46407
B20: 10 | C20: N/A | D20: N/A | E20: N\A | I20: N/A | J20: N/A | K20: N/A | L20: N/A | M20: N/A
B21: 11 | C21: N/A | D21: N/A | E21: LINGADA SFT | I21: 27280-05 | J21: N/A | K21: 46333 | L21: N/A | M21: N/A
B22: 12 | C22: N/A | D22: N/A | E22: LINGADA ELEVADOR AUXILIAR | I22: CTX285 | J22: N/A | K22: 46066 | L22: N/A | M22: N/A
B23: 13 | C23: N/A | D23: SN: 6052/25 | E23: SWIVEL ELEVADOR AUXILIAR | I23: N/A | J23: N/A | K23: N/A | L23: N/A | M23: 46079
B24: 14 | C24: N/A | D24: N/A | E24: LINGADA COFLEX | I24: 281/25 | J24: N/A | K24: 46078 | L24: N/A | M24: N/A | W24: SE ENCONTRA INSTALADA NA COFLEX
B25: 15 | C25: N/A | D25: N/A | E25: ABRAÇADEIRA DO TUBO DA SFT | I25: 0512261AA/0512262A | J25: N/A | K25: N/A | L25: N/A | M25: 46333
B26: 16 | C26: N/A | D26: N/A | E26: LINGADA ELEVADOR AUXILIAR | I26: 4108 | J26: N/A | K26: 46176 | L26: N/A | M26: N/A
B27: 17 | C27: N/A | D27: N/A | E27: SWIVEL ELEVADOR AUXILIAR | I27: 6474126 | J27: N/A
B28: 18 | C28: N/A | D28: 10OT14324 | E28: CONTAINER DE HW | I28: 36660-6 | J28: N/A | K28: 46245 | L28: N/A | M28: 46253
B29: 19 | C29: N/A | D29: N/A | E29: LINGADA DE TUBO | I29: BC-50476 | J29: N/A | K29: 46330 | L29: N/A | M29: N/A
B30: 20 | C30: N/A | D30: N/A | E30: LINGADA DE TUBO | I30: BC-53887 | J30: N/A | K30: 46213 | L30: N/A | M30: N/A
B31: 21 | C31: N/A | D31: N/A | E31: LINGADA DE TUBO | I31: BC-50491 | J31: N/A | K31: 46329 | L31: N/A | M31: N/A
B32: 22 | C32: N/A | D32: N/A | E32: N/A | I32: N/A | J32: N/A | K32: 46206 | L32: N/A | M32: 46204
B33: 23 | C33: N/A | D33: N/A | E33: N/A | I33: N/A | J33: N/A
B34: 24 | C34: N/A | D34: N/A | E34: N/A | I34: N/A | J34: N/A
B35: 25 | C35: N/A | D35: N/A | E35: N/A | I35: N/A | J35: N/A | K35: 46402 | L35: N/A | M35: 46403
B36: 26 | C36: N/A | D36: 10DRY14464 | E36: Container de Calmps TH | I36: 10DRY14464 | J36: N/A | K36: 46185 | L36: N/A | M36: 46185
B37: 27 | C37: N/A | D37: NHJU-1002288 | E37: Container do RISERSPIDER | I37: NHJ100228 | J37: N/A | K37: 46248 | L37: N/A | M37: 46248
B38: 28 | C38: N/A | D38: CBU-171 | E38: Cesta de Crossover | I38: SOS08B/00138 | J38: N/A | K38: 46399 | L38: N/A | M38: 46400
B39: 29 | C39: N/A | D39: KH - 332 | E39: Container XO | I39: SES12A/00036 | J39: N/A | K39: 13/10/2027 | L39: N/A | M39: 46722
B40: 30 | C40: N/A | D40: N/A | E40: Eslinga 2 pernas | I40: 4108 | J40: N/A | K40: 46176 | L40: N/A | M40: N/A
B41: 31 | C41: N/A | D41: 1.5MTB14576 | E41: Caixa vazia | I41: 1,5MTB14576 | J41: N/A | K41: 46206 | L41: N/A | M41: N/A
C45: LEGENDA: | E45: 60 DIAS OU MAIS PARA O VENCIMENTO
B46: =IF(E54="","",1+#REF!) | E46: MENOS DE 60 DIAS PARA O VENCIMENTO
B47: =IF(E55="","",1+B46) | E47: VENCIDO

Sheet Controle de mangueiras
A1: CONTROLE DE MANGUEIRAS | F1: Realizado por: | G1: LEANDO CARVALHO
A2: Sonda: | B2: =Geral!G5 -> SS-73 | C2: Dia: | D2: 46078 | G2: =Geral!W7 -> WAGNER SMITH
G3: GENIS HORA
A4: Supervisor: | C4: RAFAEL DAMÁSIO | D4: RODOLFO RIBEIRO | G4: YASMIN PEREIRA
A5: ITEM | B5: MEDIDAS | C5: CERTIFICADO | D5: DATA CERTIFICAÇÃO | E5: VALIDADE | F5: PRESSÃO DE TRAB. | G5: OBSERVAÇÕES
A6: 1 | B6: 1" x 25 m | C6: C4385/2024 | D6: 45373 | F6: 300 PSI | G6: ALIMENTANDO HPU
A7: 1 | B7: 1" x 23 m | C7: 22307827 | D7: 45041 | E7: 46868 | F7: 300 PSI | G7: ALIMENTANDO HPU
A8: 1 | B8: 1" x 8 m | C8: 22307888 | D8: 45041 | E8: 46868 | F8: 300 PSI | G8: CARRETEL OS
A9: 1 | B9: 1" x 25 m | C9: 22307887 | D9: 46867 | F9: 300 PSI | G9: CARRETEL HCR
A10: 1 | B10: 1/4" x 25 m | C10: C7338/2024 | D10: 45364 | F10: 18.500 PSI | G10: N2 - CONTAINER OFICINA
A11: 1 | B11: 3/8" x 25 m | C11: C4869/2024 | D11: 45404 | F11: 5.000 PSI | G11: ALIMENTANDO OMNI
A12: 1 | B12: 3/8" x 25 m | C12: C4874/2024 | D12: 45404 | F12: 5.000 PSI | G12: ALIMENTANDO OMNI
A13: 1 | B13: 1" x 25 m | C13: C7322/2024 | D13: 45456 | F13: 5.000 PSI | G13: AME 2055
A14: 1 | B14: 1" x 3 m | C14: C7332-2024 | D14: 45527 | F14: 5.000 PSI | G14: CONTAINER OFICINA
A15: 1 | B15: 1/4" x 100m | C15: 7.118-110 | E15: 46827 | F15: 26.000 PSI | G15: N2 - CONTAINER OFICINA
A16: 1 | B16: 1/4" x 25 m | C16: C4573/2024 | D16: 44321 | F16: 26.100 PSI | G16: N2 - CONTAINER OFICINA
A17: 1 | B17: 1" x 25 m | C17: MI050954 | D17: 20/01/26 | F17: 290 PSI | G17: CONTAINER OFICINA
A18: 1 | B18: 1" x 25 m | C18: MI050955 | D18: 20/01/22 | F18: 291 PSI | G18: CONTAINER OFICINA

Sheet High Torc

Sheet Dropdown
C2: Opções de localização na sonda para Equipamentos | F2: Opções de localização na sonda para Eslingas
C3: Em operação | F3: Bombordo
C4: Bombordo | F4: Booster pump
C5: Boreste | F5: Boreste
C6: Cabin Control | F6: Caixa de sobressalentes
C7: Cabine Sondador | F7: Control cabin
C8: Caixa de sobressalentes | F8: Deck de transferência
C9: Deck de transferência | F9: Double door elevator transport basket
C10: Double door elevator transport basket | F10: DPR crossover transport basket
C11: Dpr crossover transport basket | F11: Drill Floor
C12: Drill Floor | F12: Flexible flow line pipe transport basket
C13: Flexible flow line pipe transport basket | F13: Flying lead transport frame
... C43: Workshop Container | F43: Tubing hanger reeler
F44: Umbilical clamp transport basket
F45: Upper spreader bar transport skid
F46: Workshop container

Sheet Plan6
B5: TOTAL QTY. | C5: DESCRIPTION | D5: PART NUMBER
B6: 3
B7: 4 | C7: ELECTRICAL JUMPER 4 QUAD 200M FOR REMOTE DHPT READING | D7: 0495020
B8: 4 | C8: ELECTRICAL JUMPER 2 QUAD 200M FOR REMOTE DHPT READING | D8: 0495027
B9: 3 | C9: HYDRAULIC ADAPTER FOR CONNECTION 2 ANNULUS CIRCULATION LINE X STRESS JOINT | D9: 0495037
B10: 1 | C10: HYDRAULIC JUMPER KIT - DPR 5K | D10: 0495012
B11: 1 | C11: TEST DEVICES - DPR 5K | D11: 0498235
B12: 1 | C12: SPARE PARTS - DPR 5K | D12: 0498236

Sheet VERIFICADOS
C3: Número do documentos | D3: Número da revisão | E3: Equipe | F3: Supervisor
E4: Yasmin Ferreira / Gênis da Hora | F4: Jackson Ferreira
B5: Poço: | C5: SISTEMA | D5: N° JOB | E5: OPERAÇÃO IN RISER | F5: DATA: 07/03/2026
B7: CONTENTORES
B8: Tag | C8: Teste de carga | D8: ID da eslinga | E8: Certificado | F8: Validade
B9: NHJU 1002288 - Riser spider | C9: 14/08/26 | D9: NHJU 1002288 | E9: MKS180043/20 | F9: 14/08/26
B10: CBTA 468 - HW | C10: 46419 | D10: SOS12A/0023 | F10: 46389
B11: CBAD 647 - CWJ | C11: 20/06/2026 | D11: SOS05A/00052 | E11: 000094/13 | F11: 19/06/2026
B12: CBU 171 - XO | C12: 43070 | D12: SOS8B/00138 | E12: 06770/16 | F12: 46722
B13: KH 332 - NS31 | C13: 13/01/2027 | D13: SES12A/00036 | E13: BCE 2418060 | F13: 46722
B14: 10DRY14464 - Clamps | C14: 46362 | D14: 10DRY14464 | E14: HV224 | F14: 46362
B15: 100T14324 - XO | C15: 19/08/2026 | D15: 36660/8 | E15: 36660/8 | F15: 19/08/2026
B16: R 183 - CARRETEL | C16: 20/01/2027 | D16: 188542011 | E16: 188542 | F16: 20/01/2027
B17: HPU - 239 | C17: 21/03/2026 | D17: E53212 | F17: 21/03/2026
B18: WC 002 - Container oficina | C18: 28/05/2026 | D18: SS1-SM | E18: 276 | F18: 46179
B19: WV- 033 | C19: 21.03.2026 | D19: AA9840 | E19: ESS/W7834/38 | F19: 21/03/26
B20: EQUIPAMENTOS
B21: ATIVO | C21: VALIDADE | D21: ID da eslinga | E21: Certificado | F21: Validade
B22: MAC -1008 | D22: MAC-1008-52 | E22: 25-572/11 | F22: 30/10/2026
B23: R-16-15-26198 | C23: 46063 | D23: Skid N2 - 10441602 | E23: 104416/002 | F23: 46032
B24: NS-02 | C24: 13/02/2027 | D24: PÓRTICO | E24: - | F24: -
B25: LB-004 | D25: LINK | E25: - | F25: -
B26: CFP - 005 | D26: Coflex
B27: PIPIT -005/009/012 | C27: - | D27: Cavaletes | E27: - | F27: -
B28: CWJ -006/007 | C28: - | D28: Cased wear Joint | E28: - | F28: -
B29: NBP-006 | D29: Bomba Booster
B30: JUMPER
B31: ATIVO | C31: PN | D31: DESCRIÇÃO | E31: OBSERVAÇÕES | F31: CONTENTOR
B32: HJ -002 | D32: Jumper SFT
B33: HJ-011 / 008 | D33: Jumper 13 F
B34: DJ -059 / 069 /058/ 051 | D34: Jumper eletrico
B35: EFL - 111/ 112 | D35: Jumper eletrico conector / inclinometro
B36: EJ - 011 / 006 | D36: Jumper eletrico
B37: HJ-036 | D37: Jumper HCR
B38: HJ/010 | D38: Jumper 13 F | E38: SEM TAG
B39: HJ- 031 | D39: Jumper stress joint
B40: PUP / CROSSOVER / SAVER SUB / CENTRALIZADOR
B41: ATIVO | C41: PN | D41: DESCRIÇÃO | E41: OBSERVAÇÕES | F41: CONTENTOR
B42: PPJ - 020 | D42: Pup 8'
B43: PPJ - 019 | D43: Pup 8'
...
