Workbook

Sheet Geral
F3: Controle de Equipamentos Offshore | Q3: Equipe a bordo
F5: Sonda: | G5: NS-56 | L5: Poço: | M5: 7-JUB-84H-ESS | Q5: Supervisor | S5: RAPHAEL DELLATORRE | U5: Supervisor
Q6: Técnico | S6: VINICIUS PEREIRA | U6: Técnico
F7: Data: | G7: 46032 | L7: Campo: | M7: JUBARTE | Q7: Técnico | S7: ERICO MARTINS | U7: Técnico
B9: EQUIPAMENTOS
B11: Item | C11: Equip. | D11: Qtd | E11: NP | F11: NS | G11: Descrição do item | K11: Localização | L11: Dimensões em metros (C x L x A) | M11: Peso (Kg) | N11: Eslinga | O11: Solic. Material | Q11: RT de Embarque | R11: Data de Embarque | S11: RT de Desembarque | T11: Data de Desembarque | U11: Origem | V11: Destino | W11: Observação
B12: =IF(G12="","",1) -> 1 | C12: JUNTAS | D12: 0 | E12: 495094 | F12: N/A | G12: STRESS JOINT 43FT | K12: N/A | L12: - | M12: - | N12: N/A
B13: =IF(G13="","",1+B12) -> 2 | D13: 0 | E13: 495095 | F13: N/A | G13: STRESS JOINT TRANSPORT SKID | K13: N/A | L13: - | M13: - | N13: ='Controle de Eslingas'!#REF! -> #REF!
B14: =IF(G14="","",1+B13) -> 3 | D14: 0 | E14: 495096 | F14: N/A | G14: MECHANICAL RAPID CONNECTOR | K14: N/A | L14: - | M14: - | N14: N/A
B15: =IF(G15="","",1+B14) -> 4 | D15: 100 | E15: 495075 | F15: N/A | G15: PIPE DRILL 6.5/8" - XT-MF 69 | K15: Pipe Deck | M15: - | N15: N/A | Q15: 326246477 | R15: 46032 | U15: NS-43 | V15: NS-56
B16: =IF(G16="","",1+B15) -> 5 | D16: 1 | E16: 495078 | F16: PPJ-021 | G16: PUP JOINT 8' - XT-MF 69 | K16: Pipe Deck | M16: - | N16: N/A
B17: =IF(G17="","",1+B16) -> 6 | D17: 1 | E17: 495078 | F17: N/A | G17: PUP JOINT 8' - XT-MF 69 | K17: N/A | M17: - | N17: N/A
B18: =IF(G18="","",1+B17) -> 7 | D18: 3 | E18: 495077 | F18: PPJ-015 / PPJ-009 / PPJ-013 | G18: PUP JOINT 10' - XT-MF 69 | K18: N/A | M18: - | N18: N/A
B19: =IF(G19="","",1+B18) -> 8 | D19: 3 | E19: 495077 | F19: N/A | G19: PUP JOINT 10' - XT-MF 69 | K19: N/A | M19: - | N19: N/A
B20: =IF(G20="","",1+B19) -> 9 | D20: 1 | E20: 495076 | F20: N/A | G20: PUP JOINT 20' - XT-MF 69 | K20: N/A | M20: - | N20: N/A
B21: =IF(G21="","",1+B20) -> 10 | D21: 0 | E21: 495076 | F21: N/A | G21: PUP JOINT 20' - XT-MF 69 | K21: N/A | M21: - | N21: N/A
B22: =IF(G22="","",1+B21) -> 11 | D22: 1 | E22: 495081 | F22: SSUB-006 | G22: SAVER SUB BOX X BOX | K22: Pipe Deck | M22: - | N22: N/A | Q22: 326245906 | R22: 15/01/2026 | U22: NS-43 | V22: NS-56
B23: =IF(G23="","",1+B22) -> 12 | D23: 1 | E23: 495082 | F23: SSUB-010 | G23: SAVER SUB BOX X PIN | K23: Pipe Deck | M23: - | N23: N/A | Q23: 326245906 | R23: 15/01/2026 | U23: NS-43 | V23: NS-56
B24: =IF(G24="","",1+B23) -> 13 | D24: 0 | E24: 495083 | F24: SSUB-015 | G24: SAVER SUB PIN X PIN | K24: Riser Deck | M24: - | N24: N/A | Q24: 326247561 | R24: 46032
B25: =IF(G25="","",1+B24) -> 14 | D25: 0 | E25: 495106 | F25: N/A | G25: LUBRICATOR VALVE ASSEMBLY | K25: N/A | M25: - | N25: N/A
B26: =IF(G26="","",1+B25) -> 15 | D26: 0 | E26: 495084 | F26: N/A | G26: RISER ACCESSORIES TRANSPORT BASKET | K26: N/A | M26: - | N26: ='Controle de Eslingas'!#REF! -> #REF!
B27: =IF(G27="","",1+B26) -> 16 | C27: ADAPTADORES | D27: 0 | E27: 495097 | F27: N/A | G27: ADAPTER HUB 11” X RISER MC 12D | K27: N/A | M27: - | N27: N/A
B28: =IF(G28="","",1+B27) -> 17 | D28: 0 | E28: 495098 | F28: N/A | G28: ADAPTER HUB 11” X RISER MC 12DX | K28: N/A | M28: - | N28: N/A
B29: =IF(G29="","",1+B28) -> 18 | D29: 0 | E29: 495099 | F29: N/A | G29: ADAPTER XT-MF69 (BOX) X MC 8D (BOX) | K29: N/A | M29: - | N29: N/A
B30: =IF(G30="","",1+B29) -> 19 | D30: 0 | E30: 495100 | F30: N/A | G30: ADAPTER XT-MF69 (BOX) X MC 8DX (BOX) | K30: N/A | M30: - | N30: N/A
B31: =IF(G31="","",1+B30) -> 20 | D31: 0 | E31: 495101 | F31: N/A | G31: ADAPTER HUB 11” X FLANGE 11” 5X1 | K31: N/A | M31: - | N31: N/A
B32: =IF(G32="","",1+B31) -> 21 | D32: 0 | E32: 495102 | F32: N/A | G32: ADAPTER HUB 11” X FLANGE 11” 4X2 | K32: N/A | M32: - | N32: N/A
B33: =IF(G33="","",1+B32) -> 22 | D33: 0 | E33: 495103 | F33: N/A | G33: ADAPTER HUB 11” X FLANGE 11” 10K | K33: N/A | M33: - | N33: N/A
B34: =IF(G34="","",1+B33) -> 23 | D34: 0 | E34: 495104 | F34: N/A | G34: ADAPTER HUB 11” X FLANGE 13 5/8” 5X1 | K34: N/A | M34: - | N34: N/A
B35: =IF(G35="","",1+B34) -> 24 | D35: 0 | E35: 495105 | F35: N/A | G35: HUB ADAPTER TRANSPORT SKID | K35: N/A | M35: - | N35: ='Controle de Eslingas'!#REF! -> #REF!
B36: =IF(G36="","",1+B35) -> 25 | C36: CROSSOVER'S | D36: 1 | E36: 495085 | F36: CRO-003 CRO-001 | G36: CROSSOVER DPR X 4 ½” IF | K36: Pipe Deck | M36: - | N36: N/A | Q36: 326245906 | R36: 15/01/2026 | U36: NS-43 | V36: NS-56
B37: =IF(G37="","",1+B36) -> 26 | D37: 1 | E37: 495086 | F37: CRO-009 | G37: CROSSOVER DPR X 6 5/8” VAM DPR SR | K37: Pipe Deck | M37: - | N37: N/A | Q37: 326245906 | R37: 15/01/2026 | U37: NS-43 | V37: NS-56
B38: =IF(G38="","",1+B37) -> 27 | D38: 1 | E38: 495087 | F38: CRO-023 | G38: CROSSOVER DPR X 6 5/8” VAM DPR HP | K38: Pipe Deck | M38: - | N38: N/A | Q38: 326245906 | R38: 15/01/2026 | U38: NS-43 | V38: NS-56
B39: =IF(G39="","",1+B38) -> 28 | D39: 1 | E39: 495088 | F39: CRO-061 | G39: CROSSOVER DPR X 6 5/8” FH | K39: Pipe Deck | M39: - | N39: N/A | Q39: 326245906 | R39: 15/01/2026 | U39: NS-43 | V39: NS-56
B40: =IF(G40="","",1+B39) -> 29 | D40: 0 | E40: 495089 | F40: N/A | G40: CROSSOVER DPR X DP 5” NC50 | K40: Pipe Deck | M40: - | N40: N/A | Q40: 326245906 | R40: 15/01/2026 | U40: NS-43 | V40: NS-56
B41: =IF(G41="","",1+B40) -> 30 | D41: 0 | E41: 497277 | F41: N/A | G41: CROSSOVER STUB ACME PIN X XT-MF69 BOX | K41: N/A | M41: - | N41: N/A
B42: =IF(G42="","",1+B41) -> 31 | D42: 0 | E42: 497278 | F42: N/A | G42: CROSSOVER STUB ACME PIN X XT-MF69 PIN | K42: N/A | M42: - | N42: N/A
B43: =IF(G43="","",1+B42) -> 32 | D43: 0 | E43: 496064 | F43: CRO-069 | G43: CROSSOVER DPR X SWIVEL | K43: N/A | M43: - | N43: N/A
B44: =IF(G44="","",1+B43) -> 33 | D44: 0 | E44: 495093 | F44: N/A | G44: DPR CROSSOVER TRANSPORT BASKET | K44: N/A | M44: - | N44: ='Controle de Eslingas'!#REF! -> #REF!
B45: =IF(G45="","",1+B44) -> 34 | D45: 1 | E45: 495072 | F45: N/A | G45: SFT UPPER CROSSOVER 8 ¼” STUB ACME X 8 ¼” ACME BOWEN | K45: N/A | M45: - | N45: N/A
...

Sheet Controle de Eslingas
F3: =Geral!F3 -> Controle de Equipamentos Offshore | Q3: =Geral!Q3 -> Equipe a bordo
F5: =Geral!F5 -> Sonda: | G5: NS-56 | L5: =Geral!L5 -> Poço: | M5: 7-JUB-84H-ESS | Q5: =Geral!Q5 -> Supervisor | S5: Raphael Dellatore | U5: =Geral!U5 -> Supervisor
G6: Data teste de carga | M6: Data da Inspeção | Q6: =Geral!Q6 -> Técnico | S6: Erico Martins | U6: Técnico
F7: =Geral!F7 -> Data: | G7: 46032 | L7: =Geral!L7 -> Campo: | M7: =IF(Geral!M7="","",Geral!M7) -> JUBARTE | Q7: =Geral!Q7 -> Técnico | S7: Vinicius Pereira | U7: Técnico
B9: EQUIPAMENTOS
B11: Item | C11: NP | D11: NS | E11: Descrição do item | I11: ID Eslinga | J11: Especificação da Eslinga | K11: Validade da Eslinga | L11: Data Cert. equip. / Skid | M11: Validade teste carga equip. / skid | N11: Localização da Eslinga | R11: Solic. Material | S11: RT de Embarque | T11: Data de Embarque | U11: RT de Desembarque | V11: Data de Desembarque | W11: Observação
B12: 1 | C12: 495022 | D12: R-182 | E12: CARRETEL TH | I12: 188157/1 | K12: 46393 | M12: 46395 | N12: Pipe Deck -BE
B13: 2 | D13: R-182 | N13: Pipe Deck -BE
B14: 3 | C14: 432864 | D14: HTU-3002 | E14: UNIDADE DE POTÊNCIA HIDRÁULICA | I14: BC-2526034 | J14: 4 x 19mm _ 4.75T | K14: 46239 | M14: 46177 | N14: Pipe Deck -BE | S14: 325822423 | T14: 45895
B15: 4 | C15: 435631 | D15: CO-UTF3-10 | E15: CABINE DE CONTROLE | I15: 569-SM | J15: 4 x 29mm _ 12T | K15: 46129 | M15: 46129 | N15: Pipe Deck -BE | S15: 325822424 | T15: 45895
B16: 5 | C16: 420696 | D16: FU-3001 | E16: FU | I16: BC-11850 | J16: 4x 22mm_4.75T | K16: 46147 | M16: 46147 | N16: Pipe Deck -BE | S16: 325822423 | T16: 45895
B17: 6 | C17: 495011 | D17: PNL-010 | E17: PNL | I17: 11326546-0-2-001 | J17: 4 x 19mm _ 4.75T | K17: 46102 | M17: 46102 | N17: Riser Deck | S17: 326245622 | T17: 46032
B18: 7 | C18: N/A | D18: R-16-15-26172 | E18: SKID N2 | I18: 104416/0018 | J18: 4 x 19mm _ 4.75T | K18: 46206 | M18: 46207 | N18: Riser Deck | S18: 326245682 | T18: 46032
B19: 8 | C19: N/A | D19: HDBU 0141579 | E19: CAIXA DE QUÍMICOS | I19: 35365-3 | J19: 4 x 19mm _ 9,5T | K19: 46134 | M19: 46148 | N19: Riser Deck | S19: 326245758 | T19: 46032 | W19: Há um balde de graxa dentro do PNL
B20: 9 | C20: N/A | D20: NHJU2021132 | E20: CONTAINER 20" | I20: NHJU-202113 | K20: 30/04/2026 | M20: 30/04/2026 | N20: Riser Deck | S20: 326245914 | T20: 46032 | W20: CWJ/Ferramentas e Eslingas 7/8"
B21: 10 | C21: N/A | E21: PÓRTICOS (trave de sustentação das sheaves). | I21: N/A | M21: 46128 | N21: Pipe Deck - BE | W21: Certificado: 574076
B22: 11 | C22: N/A | D22: JA-533 | E22: CESTA (JUMPER) | I22: SES12A/00052 | J22: 4 x 26mm _ 8.5T | K22: 46211 | M22: 09/07/206 | N22: Riser Deck | S22: 326246126 | T22: 46032 | W22: jumpers 13f, 10f e retorno, em operação
B23: 12 | C23: 495047 | D23: 10DRY14427 | E23: Container de CLAMPS | I23: 10DRY14427 | J23: 4 X 9.8m _ 10T | K23: 46099 | M23: 46099 | N23: Riser Deck | S23: 326245683 | T23: 46032
B24: 13 | C24: N/A | D24: KH332 | E24: CONTAINER BOMONAS | I24: SES120/00036 | K24: 46359 | M24: 46359 | N24: Pipe Deck - BB | S24: 325827284 | T24: 45897 | W24: HW-525 _ Retorno e Vazia
B25: 14 | C25: N/A | D25: HDBU 0142554 | E25: CONTAINER BOMONAS | I25: 35372/16 | J25: 4x29mm _ 12T | K25: 46332 | M25: 46332 | N25: Riser Deck | S25: 326245759 | T25: 46032 | W25: HW-525 _ 10 Novas
B26: 15 | C26: N/A | D26: KH421 | E26: CONTAINER SHEAVES | I26: SOS12A/00624 | J26: 4x26mm _ 12T | K26: 46225 | M26: 46226 | N26: Riser Deck | S26: 326245912 | T26: 46032 | W26: Polias
B27: 16 | C27: N/A | D27: DNVU2004720 | E27: CONTAINER | I27: 130500021 | K27: 46248 | M27: 46247 | N27: Pipe Deck - BB | T27: 45900 | W27: Xos, Protetores, Elev. Manual, 4 mangueias de ar 1"
B28: 17 | C28: N/A | D28: JA-905 | E28: CESTA COFLEX | I28: SOS12A/00116 | K28: 46155 | M28: 46156 | N28: Riser Deck | S28: 326245763 | T28: 46032 | W28: Coflex, Jumper SFT e Jumper HCR 1"
B29: 18 | C29: N/A | E29: ESLINGA DA COFLEX | I29: L6-46081 | K29: 46240 | N29: Riser Deck | S29: 326245763 | T29: 46032 | W29: CESTA JA905
B30: 19 | C30: N/A | E30: ESLINGA DE DUAS PERNAS ELEVADOR AUXILIAR
B31: 20 | C31: N/A | D31: HDBU 0141579 | E31: Container de Quimico | I31: 35365 | K31: 46134 | M31: 46148 | N31: Riser Deck | S31: 326245758 | T31: 46032 | W31: Há um balde de graxa dentro do PNL
B32: 21 | C32: N/A | E32: Unidade hidráulica Riser Spider | J32: 4 x 13mm _ 4.3T | N32: Pipe Deck | S32: 32575531 | T32: 16/08/2025 | W32: Cert. 5929/24
B33: 22 | C33: N/A | E33: Eslinga do riser spider | N33: Pipe Deck | S33: 32575531 | T33: 16/08/2025 | W33: Cert. 5818/24
B34: 23 | C34: N/A | E34: BOMBA BOOSTER (MANÔMETROS) | I34: MN-4025 _ MN-5181 _ 7.188.84 | J34: N/A | K34: 46224 | N34: Pipe Deck - BE
B35: 24 | C35: N/A | E35: BOMBA BOOSTER (RELIEF VALVE) | J35: N/A | K35: 46224 | N35: Pipe Deck - BE
B38: 36 | C38: N/A | E38: ESLINGA DE TUBOS DPR | I38: BC06 | K38: 7\21/2026 | N38: Pipe Deck | W38: Tubos de transbordo SS-73
B39: 37 | C39: N/A | E39: ESLINGA DE TUBOS DPR | I39: BC50683 | K39: 46217 | N39: Pipe Deck | W39: Tubos de transbordo SS-73
B40: 38 | C40: N/A | E40: ESLINGA DE TUBOS DPR | I40: BC05 | K40: 46179 | N40: Pipe Deck | W40: PUP 20'
B41: 39 | C41: N/A | E41: ESLINGA DE TUBOS DPR | I41: BC03 | K41: 46179 | N41: Pipe Deck
B42: 40 | C42: N/A | E42: ESLINGA DE TUBOS DPR | I42: BC62 | K42: 46073 | N42: Pipe Deck
B43: 41 | C43: N/A | E43: ESLINGA DE TUBOS DPR | I43: BC53877 | K43: 46217 | N43: Pipe Deck
B44: 42 | C44: N/A | E44: ESLINGA DE TUBOS DPR | I44: BC50479 | K44: 46094 | N44: Pipe Deck
B45: 43 | C45: N/A | E45: ESLINGA DE TUBOS DPR | I45: BC67A | K45: 46224 | N45: Pipe Deck
B46: 44 | C46: N/A | E46: ESLINGA DE TUBOS DPR | I46: BC947 | K46: 46224 | N46: Pipe Deck
B47: 45 | C47: N/A | E47: ESLINGA DE TUBOS DPR | I47: BC15 | K47: 46179 | N47: Pipe Deck
...

Sheet Consumíveis
F3: =Geral!F3 -> Controle de Equipamentos Offshore | N3: =Geral!Q3 -> Equipe a bordo
F5: =Geral!F5 -> Sonda: | G5: =Geral!G5 -> NS-56 | J5: =Geral!L5 -> Poço: | K5: =Geral!M5 -> 7-JUB-84H-ESS | N5: =Geral!Q5 -> Supervisor | P5: =Geral!S5 -> RAPHAEL DELLATORRE | R5: =Geral!U5 -> Supervisor | T5: =Geral!W5 -> 0
G6: Data teste de carga | N6: =Geral!Q6 -> Técnico | P6: =Geral!S6 -> VINICIUS PEREIRA | R6: =Geral!U6 -> Técnico | T6: =Geral!W6 -> 0
F7: =Geral!F7 -> Data: | G7: =Geral!G7 -> 46032 | J7: =Geral!L7 -> Campo: | K7: =Geral!M7 -> JUBARTE | N7: =Geral!Q7 -> Técnico | P7: =Geral!S7 -> ERICO MARTINS | R7: =Geral!U7 -> Técnico | T7: =Geral!W7 -> 0
B9: EQUIPAMENTOS
B11: Item | C11: QNT | D11: NP | E11: NS | G11: DESCRIÇÃO | L11: APLICAÇÃO | P11: LOCALIZAÇÃO | R11: OBSERVAÇÃO
B12: 1 | C12: 1 | D12: 526315 | G12: MOBIL GEAR 600 XP 100 | P12: Cabine de controles
B13: 2 | C13: 1 | D13: 526313 | G13: LUBRAX LITH EP2 (NLGI2) | P13: Cabine de controles
B14: 3 | C14: 1 | D14: N/A | G14: MP 507 | L14: Uso Geral | P14: Cabine de controles | R14: Desemgraxante
B15: 4 | C15: 1 | D15: 524580 | E15: N/A | G15: KOPR-KOTE | L15: Rosca XTMF-69 | P15: Cabine de controles
B16: 5 | C16: 0 | D16: 526314 | E16: N/A | G16: TELLUS 46 | P16: Cabine de controles | R16: BALDE PRETO
B17: 6 | C17: 1 | D17: CL031-017-01 | E17: N/A | G17: WD-40 SPRAY 300ML | P17: Cabine de controles
B18: 7 | C18: 2 | D18: N/A | E18: N/A | G18: LIMPA CONTATO | P18: Cabine de controles
B19: 8 | C19: 3 | D19: N/A | E19: N/A | G19: ÁLCOOL ISOPROPILICO - 500ml | P19: Cabine de controles | U19: b
C20: 2 | D20: 524242 | G20: MARKEY VERMELHO | P20: Cabine de controles
C21: 1 | D21: N/A | E21: N/A | G21: LOCTITE 243 | P21: Cabine de controles
C22: 1 | D22: N/A | E22: N/A | G22: VG 10 | P22: Lubrifil
C23: 1 | D23: N/A | E23: N/A | G23: Óleo Padrão Pershy CS 1000 - 1L | P23: Cabine de controles
B24: =IF(G24="","",B23+1) -> 1 | C24: 0 | D24: N/A | E24: N/A | G24: Protetor Solar
B25: =IF(G25="","",B24+1) -> 2 | C25: 11 | D25: N/A | E25: N/A | G25: HW-525 | R25: CESTA CBAD-601 _ PIPE DECK
B26: =IF(G26="","",B25+1) -> 3 | C26: 2 | D26: N/A | E26: N/A | G26: ENERPAC HYDRAULIC OIL HF-100 | P26: Cabine de controles | R26: 2L
B27: =IF(#REF!="","",B26+1) -> #REF! | C27: 0 | D27: N/A | E27: N/A | G27: LUBRICANT TUFLUBE ALLWEATHER 18KG (ROCOL | L27: Rolamento | P27: Cabine de controles | R27: 5Kg
B28: =IF(G28="","",B27+1) -> #REF! | C28: 1 | D28: N/A | E28: N/A | G28: SACO DE TRAPO | L28: LIMPEZA/DERRAMAMENTO | P28: Cabine de controles
B29: =IF(G29="","",B28+1) -> #REF! | C29: 1 | D29: N/A | E29: N/A | G29: SACO DE MANTA ABSORVENTE | L29: LIMPEZA/DERRAMAMENTO | P29: Cabine de controles
B30: =IF(G30="","",B29+1) -> #REF! | C30: 1 | D30: N/A | E30: N/A | G30: LUBRAX CALCIUM GR2
B31: =IF(G31="","",B30+1) -> #REF! | C31: 0 | D31: N/A | E31: N/A | G31: LUBRAX CALCIUM ECO 2
B32: =IF(G32="","",B31+1) -> #REF! | C32: 0 | D32: N/A | E32: N/A | G32: MOBILGEAR SHC XMP320 SINTHETIC WIND TURBINE | L32: ÓLEO DO MOTOR | N32: ÓLEO DO MOTOR
B33: =IF(G33="","",B32+1) -> #REF! | C33: 0 | D33: N/A | E33: N/A | G33: Óleo Hidráulico HF 101N (Enerpac) | L33: INTENSIFICADOR | N33: INTENSIFICADOR
B34: =IF(G34="","",B33+1) -> #REF! | C34: 0 | D34: N/A | E34: N/A | G34: Óleo Hidráulico HF 100N (Enerpac) | L34: INTENSIFICADOR | N34: INTENSIFICADOR
B35: =IF(G35="","",B34+1) -> #REF! | C35: 1 | D35: N/A | E35: N/A | G35: TELLUS S2 M
B36: =IF(G36="","",B35+1) -> #REF! | C36: 0 | D36: N/A | E36: N/A | G36: PETRONAS TUTE
B37: =IF(G37="","",B36+1) -> #REF! | C37: 1 | D37: N/A | E37: N/A | G37: LUBRICANT TUFLUBE ALLWEATHER 4KG | L37: GRAXA PARA ENGRENAGEM
B38: =IF(G38="","",B37+1) -> #REF! | C38: 0 | D38: 523800 | E38: N/A | G38: MOBILGEAR 636
B39: =IF(G39="","",B38+1) -> #REF! | C39: 0 | D39: N/A | E39: N/A | G39: MOLYKOTE 1000 | L39: CLAMPS
B40: =IF(G40="","",B39+1) -> #REF! | C40: 0 | D40: N/A | E40: N/A | G40: OLEO NARO 32 | L40: ENERPAC CARRETEL TH NO PARA O INTENSIFICADOR
B41: =IF(G41="","",B40+1) -> #REF! | C41: 0 | G41: GREASE RENOLITE EP2 12.5KG TRANSLUCENT B
B42: =IF(G42="","",B41+1) | D42: - | E42: -
B43: =IF(G43="","",B42+1) | D43: - | E43: -
B44: =IF(G44="","",B43+1) | D44: - | E44: -
B45: =IF(G45="","",B44+1) | D45: - | E45: -
...

Sheet High Torc

Sheet Dropdown
C2: Opções de localização na sonda para Equipamentos | F2: Opções de localização na sonda para Eslingas
C3: Em operação | F3: Bombordo
C4: Bombordo | F4: Booster pump
C5: Boreste | F5: Boreste
C6: Cabin Control | F6: Caixa de sobressalentes
C7: Cabine Sondador | F7: Control cabin
C8: Caixa de sobressalentes | F8: Deck de transferência
C9: Deck de transferência | F9: Double door elevator transport basket
C10: Double door elevator transport basket | F10: DPR crossover transport basket
C11: Dpr crossover transport basket | F11: Drill Floor
C12: Drill Floor | F12: Flexible flow line pipe transport basket
C13: Flexible flow line pipe transport basket | F13: Flying lead transport frame
... C43: Workshop Container | F43: Tubing hanger reeler
F44: Umbilical clamp transport basket
F45: Upper spreader bar transport skid
F46: Workshop container

Sheet Plan6
B5: TOTAL QTY. | C5: DESCRIPTION | D5: PART NUMBER
B6: 3
B7: 4 | C7: ELECTRICAL JUMPER 4 QUAD 200M FOR REMOTE DHPT READING | D7: 0495020
B8: 4 | C8: ELECTRICAL JUMPER 2 QUAD 200M FOR REMOTE DHPT READING | D8: 0495027
B9: 3 | C9: HYDRAULIC ADAPTER FOR CONNECTION 2 ANNULUS CIRCULATION LINE X STRESS JOINT | D9: 0495037
B10: 1 | C10: HYDRAULIC JUMPER KIT - DPR 5K | D10: 0495012
B11: 1 | C11: TEST DEVICES - DPR 5K | D11: 0498235
B12: 1 | C12: SPARE PARTS - DPR 5K | D12: 0498236

Sheet Mangueiras
A1: CONTROLE DE MANGUEIRAS | F1: Realizado por:
A2: Sonda: | B2: NS-43 | C2: Dia: | D2: 20/11/2025
A4: Supervisor: | C4: RAPHAEL DELLATORRE
A5: ITEM | B5: MEDIDAS | C5: CERTIFICADO | D5: DATA CERTIFICAÇÃO | E5: VALIDADE | F5: PRESSÃO DE TRAB. | G5: OBSERVAÇÕES
A6: HJ-034 | B6: HOSE ASSEMBLY 1 IN ID X 25M LG | C6: Sem identificação | D6: Sem identificação | E6: Sem identificação | F6: Sem identificação | G6: Retorno
A7: 49188 | B7: 1/4" x 25m | C7: 18469/2025 | D7: 25/06/2025 | F7: 18000 psi | G7: MANGUEIRA MICROPERFURADA PARA NITROGÊNIO
A8: MI048.77 | B8: 1' x 25m | D8: 03/09/2025 | F8: 300psi | G8: Mangueira de ar
A9: MI048.73 | B9: 1' x 25m | D9: 03/09/2025 | F9: 300psi | G9: Mangueira de ar
A10: MI048.74 | B10: 1' x 25m | D10: 03/09/2025 | F10: 300psi | G10: Mangueira de ar
A11: MI048.71 | B11: 1' x 25m | D11: 03/09/2025 | F11: 300psi | G11: Mangueira de ar
A12: MI048.78 | B12: 1' x 25m | D12: 03/09/2025 | F12: 300psi | G12: Mangueira de ar
A13: MI048.79 | B13: 1' x 25m | D13: 03/09/2025 | F13: 300psi | G13: Mangueira de ar
A14: MI048.80 | B14: 1' x 25m | D14: 45725 | E14: 46090
A15: 46429 | B15: 3/8" x 15m | C15: 16753/2025 | D15: 46361 | E15: 46361 | F15: 10.000 psi | G15: Container de Ferramentas/Cabine
A16: 4718 | B16: 3/8" x 15,73m | C16: 13457/2025 | D16: 13/02/2026 | E16: 13/02/2026 | F16: 5.000 psi | G16: Container de Ferramentas/Cabine
A17: 46430 | B17: 1/4" x 15m | C17: 16752/2025 | D17: 12/5/2025 | E17: 12/5/2026 | F17: 10.000 psi | G17: Container de Ferramentas/Cabine
A18: 46431 | B18: 1/4" x 15m | C18: 16755/2025 | D18: 12/05/2025 | E18: 12/5/2026 | F18: 10.000 psi | G18: Container de Ferramentas/Cabine
A19: 47192 | B19: 3/8" x 3,09m | C19: 13425/2025 | D19: 13/02/2025 | E19: 13/02/2026 | F19: 5.000 psi | G19: Container de Ferramentas/Cabine
A20: 47171 | B20: 3/8 x 3,25m | C20: 13454/2025 | D20: 13/02/2025 | E20: 13/02/2026 | F20: 5.000 psi | G20: Container de Ferramentas/Cabine
A21: 47191 | B21: 3/8" x 1,61m | C21: 13458/2025 | D21: 13/02/2025 | E21: 13/02/2026 | F21: 5.000 psi | G21: Container de Ferramentas/Cabine
A22: 49612 | B22: 1/4" 3,1m | C22: 7850/2024 | D22: 45421 | E22: 45786 | F22: 18.560 psi | G22: Container de Ferramentas/Cabine
A23: 49623 | B23: 1/4" x 25m | C23: 7846/2024 | D23: 45421 | E23: 45786 | F23: 18.560 psi | G23: Container de Ferramentas/Cabine
B24: 1/4" x 15m | C24: 7855/2024 | D24: 45421 | E24: 45786 | F24: 10.000 psi | G24: Container de Ferramentas/Cabine
A25: 49611 | B25: 1/4" x 3,1m | C25: 7851/2024 | D25: 45421 | E25: 45786 | F25: 18.560 psi | G25: Container de Ferramentas/Cabine
B26: 1/4" x 3,1m | C26: 7852/2024 | D26: 45421 | E26: 45786 | F26: 18.560 psi | G26: Container de Ferramentas/Cabine
A27: 49615 | B27: 1/4'' 15 m | D27: 45421 | E27: 45786 | F27: 18.560 psi | G27: Container de Ferramentas/Cabine
A28: 48731-4 | B28: 1 "x 25m | C28: 12012/2024 | D28: 45942 | E28: 10/12/2025 | F28: 150 psi | G28: Mangueira de Ar. Container de Ferramentas/Cabine

Sheet EQP. MEDIÇÃO
F3: =Geral!F3 -> Controle de Equipamentos Offshore | Q3: =Geral!Q3 -> Equipe a bordo
F5: =Geral!F5 -> Sonda: | G5: NS-43 | L5: =Geral!L5 -> Poço: | M5: 7-RO-190H-RJS | Q5: =Geral!Q5 -> Supervisor | S5: RAPHAEL DELLATORRE | U5: =Geral!U5 -> Supervisor
G6: Data teste de carga | M6: Data da Inspeção | Q6: =Geral!Q6 -> Técnico | S6: YASMIN FERREIRA | U6: Técnico
F7: =Geral!F7 -> Data: | G7: 45970 | L7: =Geral!L7 -> Campo: | M7: =IF(Geral!M7="","",Geral!M7) -> JUBARTE | Q7: =Geral!Q7 -> Técnico | U7: Técnico
B9: EQUIPAMENTOS
B11: Item | C11: NP | D11: NS | E11: Descrição do item | I11: ID Eslinga | J11: Especificação da Eslinga | K11: Validade da Eslinga | L11: Data Cert. equip. / Skid | M11: Validade teste carga equip. / skid | N11: Localização da Eslinga | R11: Solic. Material | S11: RT de Embarque | T11: Data de Embarque | U11: RT de Desembarque | V11: Data de Desembarque | W11: Observação
B12: 26 | C12: N/A | D12: TDR-STR-0004 | E12: TDR | L12: 46158 | N12: Pipe Deck
B13: 27 | C13: N/A | D13: MT-04 | E13: MULTIMETRO | L13: 46000 | N13: Riser deck
B14: 28 | C14: N/A | D14: MT-15 | E14: MULTIMETRO | L14: 46149
B15: 29 | C15: N/A | D15: ME-34 | E15: MEGÔMETRO | L15: 46130 | N15: Riser deck
B16: 30 | C16: N/A | D16: ME-09 | E16: MEGÔMETRO | L16: 46246
B17: 31 | C17: N/A | D17: TQ-15 | E17: TORQUÍMETRO para CWJ | L17: 46008 | N17: Pipe Deck
B18: 32 | C18: N/A | D18: TQ-38 | E18: TORQUIMETRO 40-200 N.m | L18: 45889 | N18: Pipe Deck
B19: 33 | C19: N/A | D19: PQ-10 | E19: PAQUÍMETRO | L19: 45885 | N19: Pipe Deck
B20: 34 | C20: N/A | D20: PQ-19 | E20: PAQUÍMETRO | L20: 45898 | N20: Pipe Deck
B21: 35 | C21: N/A | D21: PQ-09 | E21: TORQUÍMENTRO DO KIT CLAMPS (TLCMP-007) | L21: 21/08/2026 | N21: Pipe Deck
C82: LEGENDA: | E82: 60 DIAS OU MAIS PARA O VENCIMENTO
E83: MENOS DE 60 DIAS PARA O VENCIMENTO
E84: VENCIDO
B85: =IF(E90="","",1+B84)
B86: =IF(E91="","",1+B85)
B87: =IF(E92="","",1+B86)
